import 'unittest' as unittest

function first_function()
{
    try
    {
        second_function()
    }
    catch (Exception as ex)
    {
        unittest.Assert.that(ex.message()).is_equal_to('My exception has a message')
        rethrow ex
    }
}

function second_function()
{
    throw Exception("My exception has a message")
}

function test_empty_try_finally() {
    try {
        var message = "inside the try"
    }
    finally {
        var message = 'finally after try'
    }
}

function test_exception_handling() {
    unittest.Assert.that(first_function).throws()
}
